<?xml version="1.0" encoding="utf-8"?>

<robot name="alexbotmini" >

  <mujoco>
    <compiler meshdir="../meshes" discardvisual="false"/>
  </mujoco>

  <!-- <mujoco>
  <compiler 
    meshdir="" 
    balanceinertia="true" 
    discardvisual="false" />
  </mujoco>

 
  <link name="world"></link>
  <joint name="floating_base_joint" type="floating">
    <parent link="world" />
    <child link="base_link" />
  </joint> -->

 <!-- [CAUTION] uncomment above mujoco part and floarting joint part when convert to mujoco -->

  <link
    name="base_link">
    <inertial>
      <origin
        xyz="-5.403E-06 0.00054897 -0.042272"
        rpy="0 0 0" />
      <mass
        value="5" />
      <inertia
        ixx="0.03941761"
        ixy="-0.00021040"
        ixz="0.00000490"
        iyy="0.02531477"
        iyz="0.00022476"
        izz="0.02090025" />
    </inertial>
    <visual>
      <origin
        xyz="0 0 0"
        rpy="0 0 0" />
      <geometry>
        <mesh
          filename="../meshes/base_link.STL" />
      </geometry>
      <material
        name="">
        <color
          rgba="0.75294 0.75294 0.75294 1" />
      </material>
    </visual>
    <collision>
      <origin
        xyz="0 0 -0.06"
        rpy="0 0 0" />
      <geometry>
        <box name="baselink" size="0.16 0.16 0.12"/>
      </geometry>
    </collision>
  </link>
    <link
    name="leftlink1">
    <inertial>
      <origin
        xyz="-0.021825 0.017592 6.1019E-06"
        rpy="0 0 0" />
      <mass
        value="1.3062404" />
      <inertia
        ixx="0.0040457"
        ixy="0.0000842"
        ixz="-0.0000027"
        iyy="0.0019129"
        iyz="0.0000049"
        izz="0.0042188" />
    </inertial>
    <visual>
      <origin
        xyz="0 0 0"
        rpy="0 0 0" />
      <geometry>
        <mesh
          filename="../meshes/leftlink1.STL" />
      </geometry>
      <material
        name="">
        <color
          rgba="0.79216 0.81961 0.93333 1" />
      </material>
    </visual>

  </link>
  <joint
    name="leftjoint1"
    type="revolute">
    <origin
      xyz="0 0.091 -0.08"
      rpy="0 0 0" />
    <parent
      link="base_link" />
    <child
      link="leftlink1" />
    <axis
      xyz="0 1 0" />
    <limit
      lower="-1"
      upper="1"
      effort="96"
      velocity="10.47" />
  </joint>
  <link
    name="leftlink2">
    <inertial>
      <origin
        xyz="0.014318 8.5098E-07 -0.072113"
        rpy="0 0 0" />
      <mass
        value="1.7560393" />
      <inertia
        ixx="0.0136219"
        ixy="-0.0000051"
        ixz="0.0060673"
        iyy="0.0191693"
        iyz="0.0000045"
        izz="0.0076415" />
    </inertial>
    <visual>
      <origin
        xyz="0 0 0"
        rpy="0 0 0" />
      <geometry>
        <mesh
          filename="../meshes/leftlink2.STL" />
      </geometry>
      <material
        name="">
        <color
          rgba="0.89804 0.91765 0.92941 1" />
      </material>
    </visual>
    <collision>
      <origin
        xyz="0.08 0 -0.08"
        rpy="0 0 0" />
      <geometry>
        <box name="leftlink2" size="0.15 0.08 0.20"/>
      </geometry>
    </collision>
  </link>
  <joint
    name="leftjoint2"
    type="revolute">
    <origin
      xyz="-0.0816 0.052 -0.0002344"
      rpy="0 0 0" />
    <parent
      link="leftlink1" />
    <child
      link="leftlink2" />
    <axis
      xyz="-1 0 0" />
    <limit
      lower="-1"
      upper="1"
      effort="51"
      velocity="6.17" />
  </joint>
  <link
    name="leftlink3">
    <inertial>
      <origin
        xyz="-0.00024643 0.0080676 -0.048991"
        rpy="0 0 0" />
      <mass
        value="2.1149564" />
      <inertia
        ixx="0.0347571"
        ixy="0.0000811"
        ixz="0.0000036"
        iyy="0.0342630"
        iyz="-0.0025562"
        izz="0.0039739" />
    </inertial>
    <visual>
      <origin
        xyz="0 0 0"
        rpy="0 0 0" />
      <geometry>
        <mesh
          filename="../meshes/leftlink3.STL" />
      </geometry>
      <material
        name="">
        <color
          rgba="0.89804 0.91765 0.92941 1" />
      </material>
    </visual>
    <collision>
      <origin
        xyz="0 0 -0.14"
        rpy="1.57 0 0" />
      <geometry>
        <cylinder name="leftlink3" length="0.1" radius="0.045"/>
      </geometry>
    </collision>
  </link>
  <joint
    name="leftjoint3"
    type="revolute">
    <origin
      xyz="0.078 0 -0.15861"
      rpy="0 0 0" />
    <parent
      link="leftlink2" />
    <child
      link="leftlink3" />
    <axis
      xyz="0 0 -1" />
    <limit
      lower="-1"
      upper="1"
      effort="51"
      velocity="6.17" />
  </joint>
  <link
    name="leftlink4">
    <inertial>
      <origin
        xyz="-0.0054767 -0.017536 -0.11984"
        rpy="0 0 0" />
      <mass
        value="2.1749387" />
      <inertia
        ixx="0.0524207"
        ixy="-0.0002599"
        ixz="-0.0016500"
        iyy="0.0524957"
        iyz="-0.0071519"
        izz="0.0035599" />
    </inertial>
    <visual>
      <origin
        xyz="0 0 0"
        rpy="0 0 0" />
      <geometry>
        <mesh
          filename="../meshes/leftlink4.STL" />
      </geometry>
      <material
        name="">
        <color
          rgba="0.89804 0.91765 0.92941 1" />
      </material>
    </visual>
    <collision>
      <origin
        xyz="0 -0.02 -0.15"
        rpy="0 0 0" />
      <geometry>
        <box name="leftlink4" size="0.07 0.08 0.16"/>
      </geometry>
    </collision>
  </link>
  <joint
    name="leftjoint4"
    type="revolute">
    <origin
      xyz="0 0.027 -0.142"
      rpy="0 0 0" />
    <parent
      link="leftlink3" />
    <child
      link="leftlink4" />
    <axis
      xyz="0 1 0" />
    <limit
      lower="-1"
      upper="1"
      effort="96"
      velocity="10.47" />
  </joint>
  <link
    name="leftlink5">
    <inertial>
      <origin
        xyz="-1.2466E-08 -1.3708E-08 -3.3307E-16"
        rpy="0 0 0" />
      <mass
        value="0.017311" />
      <inertia
        ixx="1.816E-06"
        ixy="-5.4756E-15"
        ixz="-1.829E-13"
        iyy="1.28E-06"
        iyz="1.6181E-13"
        izz="1.529E-06" />
    </inertial>
    <visual>
      <origin
        xyz="0 0 0"
        rpy="0 0 0" />
      <geometry>
        <mesh
          filename="../meshes/leftlink5.STL" />
      </geometry>
      <material
        name="">
        <color
          rgba="0.89804 0.91765 0.92941 1" />
      </material>
    </visual>

  </link>
  <joint
    name="leftjoint5"
    type="revolute">
    <origin
      xyz="-0.0062437 -0.023 -0.289"
      rpy="0 0 0" />
    <parent
      link="leftlink4" />
    <child
      link="leftlink5" />
    <axis
      xyz="0 -1 0" />
    <limit
      lower="-1"
      upper="1"
      effort="30"
      velocity="13" />
  </joint>
  <link
    name="leftlink6">
    <inertial>
      <origin
        xyz="0.029447 0.0002491 -0.034298"
        rpy="0 0 0" />
      <mass
        value="0.5" />
      <inertia
        ixx="0.0009212"
        ixy="-0.0000042"
        ixz="0.0006845"
        iyy="0.0032190"
        iyz="0.0000046"
        izz="0.0027864" />
    </inertial>
    <visual>
      <origin
        xyz="0 0 0"
        rpy="0 0 0" />
      <geometry>
        <mesh
          filename="../meshes/leftlink6.STL" />
      </geometry>
      <material
        name="">
        <color
          rgba="0.89804 0.91765 0.92941 1" />
      </material>
    </visual>
    <collision>
      <origin
        xyz="0.05 0 -0.048"
        rpy="0 0 1.57" />
      <geometry>
        <box size="0.1 0.24 0.01"/>
      </geometry>
    </collision>
  </link>
  <joint
    name="leftjoint6"
    type="revolute">
    <origin
      xyz="0 0 0"
      rpy="0 0 0" />
    <parent
      link="leftlink5" />
    <child
      link="leftlink6" />
    <axis
      xyz="1 0 0" />
    <limit
      lower="-0"
      upper="0"
      effort="30"
      velocity="13" />
  </joint>
  <link
    name="rightlink1">
    <inertial>
      <origin
        xyz="-0.021825 -0.017467 1.1831E-05"
        rpy="0 0 0" />
      <mass
        value="1.3062404" />
      <inertia
        ixx="0.00399966"
        ixy="-0.00010632"
        ixz="-0.00000054"
        iyy="0.00191089"
        iyz="0.00000744"
        izz="0.00417477" />
    </inertial>
    <visual>
      <origin
        xyz="0 0 0"
        rpy="0 0 0" />
      <geometry>
        <mesh
          filename="../meshes/rightlink1.STL" />
      </geometry>
      <material
        name="">
        <color
          rgba="0.79216 0.81961 0.93333 1" />
      </material>
    </visual>

  </link>
  <joint
    name="rightjoint1"
    type="revolute">
    <origin
      xyz="0 -0.089 -0.08"
      rpy="0 0 0" />
    <parent
      link="base_link" />
    <child
      link="rightlink1" />
    <axis
      xyz="0 -1 0" />
    <limit
      lower="-1"
      upper="1"
      effort="96"
      velocity="10.47" />
  </joint>
  <link
    name="rightlink2">
    <inertial>
      <origin
        xyz="0.014349 -3.4419E-05 -0.072113"
        rpy="0 0 0" />
      <mass
        value="1.7560393" />
      <inertia
        ixx="0.01363482"
        ixy="-0.00001591"
        ixz="0.00606787"
        iyy="0.01917834"
        iyz="-0.00000510"
        izz="0.00766341" />
    </inertial>
    <visual>
      <origin
        xyz="0 0 0"
        rpy="0 0 0" />
      <geometry>
        <mesh
          filename="../meshes/rightlink2.STL" />
      </geometry>
      <material
        name="">
        <color
          rgba="0.89804 0.91765 0.92941 1" />
      </material>
    </visual>
    <collision>
      <origin
        xyz="0.08 0 -0.08"
        rpy="0 0 0" />
      <geometry>
        <box name="rightlink2" size="0.15 0.08 0.20"/>
      </geometry>
    </collision>
  </link>
  <joint
    name="rightjoint2"
    type="revolute">
    <origin
      xyz="-0.0816 -0.052 0.0002344"
      rpy="0 0 0" />
    <parent
      link="rightlink1" />
    <child
      link="rightlink2" />
    <axis
      xyz="-1 0 0" />
    <limit
      lower="-1"
      upper="1"
      effort="51"
      velocity="6.17" />
  </joint>
  <link
    name="rightlink3">
    <inertial>
      <origin
        xyz="7.7184E-05 -0.0080763 -0.048796"
        rpy="0 0 0" />
      <mass
        value="2.115" />
      <inertia
        ixx="0.03469118"
        ixy="-0.00009815"
        ixz="-0.00001928"
        iyy="0.03417687"
        iyz="0.00258761"
        izz="0.00395370" />
    </inertial>
    <visual>
      <origin
        xyz="0 0 0"
        rpy="0 0 0" />
      <geometry>
        <mesh
          filename="../meshes/rightlink3.STL" />
      </geometry>
      <material
        name="">
        <color
          rgba="0.89804 0.91765 0.92941 1" />
      </material>
    </visual>
    <collision>
      <origin
        xyz="0 0 -0.14"
        rpy="1.57 0 0" />
      <geometry>
        <cylinder name="rightlink3" length="0.1" radius="0.045"/>
      </geometry>
    </collision>
  </link>
  <joint
    name="rightjoint3"
    type="revolute">
    <origin
      xyz="0.078 0 -0.15861"
      rpy="0 0 0" />
    <parent
      link="rightlink2" />
    <child
      link="rightlink3" />
    <axis
      xyz="0 0 -1" />
    <limit
      lower="-1"
      upper="1"
      effort="51"
      velocity="6.17" />
  </joint>
  <link
    name="rightlink4">
    <inertial>
      <origin
        xyz="-0.00548131462526676 0.0175313657999077 -0.119815862806828"
        rpy="0 0 0" />
      <mass
        value="2.1749387" />
      <inertia
        ixx="0.05239847"
        ixy="-0.00026116"
        ixz="-0.00165200"
        iyy="0.05247079"
        iyz="-0.00711487"
        izz="0.00356264" />
    </inertial>
    <visual>
      <origin
        xyz="0 0 0"
        rpy="0 0 0" />
      <geometry>
        <mesh
          filename="../meshes/rightlink4.STL" />
      </geometry>
      <material
        name="">
        <color
          rgba="0.898039215686275 0.917647058823529 0.929411764705882 1" />
      </material>
    </visual>
    <collision>
      <origin
        xyz="0 0.02 -0.15"
        rpy="0 0 0" />
      <geometry>
        <box name="rightlink4" size="0.07 0.08 0.16"/>
      </geometry>
    </collision>
  </link>
  <joint
    name="rightjoint4"
    type="revolute">
    <origin
      xyz="0 -0.027 -0.142"
      rpy="0 0 0" />
    <parent
      link="rightlink3" />
    <child
      link="rightlink4" />
    <axis
      xyz="0 -1 0" />
    <limit
      lower="-1"
      upper="1"
      effort="96"
      velocity="10.47" />
  </joint>
  <link
    name="rightlink5">
    <inertial>
      <origin
        xyz="2.0918E-06 3.5218E-08 2.6626E-09"
        rpy="0 0 0" />
      <mass
        value="0.017311" />
      <inertia
        ixx="1.8715E-06"
        ixy="-3.5362E-12"
        ixz="8.1116E-12"
        iyy="1.3811E-06"
        iyz="4.0896E-12"
        izz="1.5845E-06" />
    </inertial>
    <visual>
      <origin
        xyz="0 0 0"
        rpy="0 0 0" />
      <geometry>
        <mesh
          filename="../meshes/rightlink5.STL" />
      </geometry>
      <material
        name="">
        <color
          rgba="0.89804 0.91765 0.92941 1" />
      </material>
    </visual>

  </link>
  <joint
    name="rightjoint5"
    type="revolute">
    <origin
      xyz="-0.0062206 0.025 -0.289"
      rpy="0 0 0" />
    <parent
      link="rightlink4" />
    <child
      link="rightlink5" />
    <axis
      xyz="0 1 0" />
    <limit
      lower="-1"
      upper="1"
      effort="30"
      velocity="13.67" />
  </joint>
  <link
    name="rightlink6">
    <inertial>
      <origin
        xyz="0.022759 -0.00027434 -0.031905"
        rpy="0 0 0" />
      <mass
        value="0.5" />
      <inertia
        ixx="0.00087211"
        ixy="-0.00000369"
        ixz="0.00064057"
        iyy="0.00304549"
        iyz="-0.0000040"
        izz="0.00263391" />
    </inertial>
    <visual>
      <origin
        xyz="0 0 0"
        rpy="0 0 0" />
      <geometry>
        <mesh
          filename="../meshes/rightlink6.STL" />
      </geometry>
      <material
        name="">
        <color
          rgba="0.89804 0.91765 0.92941 1" />
      </material>
    </visual>
    <collision>
      <origin
        xyz="0.05 0 -0.048"
        rpy="0 0 1.57" />
      <geometry>
         <box size="0.1 0.24 0.01"/>
      </geometry>
    </collision>
  </link>
  <joint
    name="rightjoint6"
    type="revolute">
    <origin
      xyz="0 0 0"
      rpy="0 0 0" />
    <parent
      link="rightlink5" />
    <child
      link="rightlink6" />
    <axis
      xyz="-1 0 0" />
    <limit
      lower="-1"
      upper="1"
      effort="30"
      velocity="13.67" />
  </joint>

</robot>