<?xml version="1.0" encoding="utf-8"?>
<!-- This URDF was automatically created by SolidWorks to URDF Exporter! Originally created by Stephen Brawner (brawner@gmail.com) 
     Commit Version: 1.6.0-4-g7f85cfe  Build Version: 1.6.7995.38578
     For more information, please see http://wiki.ros.org/sw_urdf_exporter -->
<robot
  name="Alexbotmini_lowerbody">
  <link
    name="base_link">
    <inertial>
      <origin
        xyz="-5.403E-06 0.00054897 -0.042272"
        rpy="0 0 0" />
      <mass
        value="4.2205" />
      <inertia
        ixx="0.0043789"
        ixy="-2.4463E-07"
        ixz="4.0802E-07"
        iyy="0.002838"
        iyz="-2.0869E-05"
        izz="0.0045167" />
    </inertial>
    <visual>
      <origin
        xyz="0 0 0"
        rpy="0 0 0" />
      <geometry>
        <mesh
          filename="../meshes/base_link.STL" />
      </geometry>
      <material
        name="">
        <color
          rgba="0.75294 0.75294 0.75294 1" />
      </material>
    </visual>
    <collision>
      <origin
        xyz="0 0 -0.06"
        rpy="0 0 0" />
      <geometry>
        <box name="baselink" size="0.16 0.16 0.12"/>
      </geometry>
    </collision>
  </link>
  <link
    name="rightlink1">
    <inertial>
      <origin
        xyz="-0.021825 -0.017467 1.1831E-05"
        rpy="0 0 0" />
      <mass
        value="0.50984" />
      <inertia
        ixx="0.00066856"
        ixy="-0.00013037"
        ixz="-3.944E-07"
        iyy="0.0010011"
        iyz="9.1641E-08"
        izz="0.00078068" />
    </inertial>
    <visual>
      <origin
        xyz="0 0 0"
        rpy="0 0 0" />
      <geometry>
        <mesh
          filename="../meshes/rightlink1.STL" />
      </geometry>
      <material
        name="">
        <color
          rgba="0.79216 0.81961 0.93333 1" />
      </material>
    </visual>

  </link>
  <joint
    name="rightjoint1"
    type="revolute">
    <origin
      xyz="0 -0.089 -0.08"
      rpy="0 0 0" />
    <parent
      link="base_link" />
    <child
      link="rightlink1" />
    <axis
      xyz="0 -1 0" />
    <limit
      lower="-1"
      upper="1"
      effort="96"
      velocity="12" />
  </joint>
  <link
    name="rightlink2">
    <inertial>
      <origin
        xyz="0.014349 -3.4419E-05 -0.072113"
        rpy="0 0 0" />
      <mass
        value="0.95964" />
      <inertia
        ixx="0.0034288"
        ixy="-8.6772E-08"
        ixz="0.00050557"
        iyy="0.0034547"
        iyz="-9.7904E-08"
        izz="0.001276" />
    </inertial>
    <visual>
      <origin
        xyz="0 0 0"
        rpy="0 0 0" />
      <geometry>
        <mesh
          filename="../meshes/rightlink2.STL" />
      </geometry>
      <material
        name="">
        <color
          rgba="0.89804 0.91765 0.92941 1" />
      </material>
    </visual>
    <collision>
      <origin
        xyz="0.08 0 -0.08"
        rpy="0 0 0" />
      <geometry>
        <box name="rightlink2" size="0.15 0.08 0.20"/>
      </geometry>
    </collision>
  </link>
  <joint
    name="rightjoint2"
    type="revolute">
    <origin
      xyz="-0.0816 -0.052 0.0002344"
      rpy="0 0 0" />
    <parent
      link="rightlink1" />
    <child
      link="rightlink2" />
    <axis
      xyz="-1 0 0" />
    <limit
      lower="-1"
      upper="1"
      effort="51"
      velocity="6.28" />
  </joint>
  <link
    name="rightlink3">
    <inertial>
      <origin
        xyz="7.7184E-05 -0.0080763 -0.048796"
        rpy="0 0 0" />
      <mass
        value="0.81499" />
      <inertia
        ixx="0.0022322"
        ixy="1.9193E-06"
        ixz="2.7985E-06"
        iyy="0.0026109"
        iyz="2.4441E-05"
        izz="0.0012062" />
    </inertial>
    <visual>
      <origin
        xyz="0 0 0"
        rpy="0 0 0" />
      <geometry>
        <mesh
          filename="../meshes/rightlink3.STL" />
      </geometry>
      <material
        name="">
        <color
          rgba="0.89804 0.91765 0.92941 1" />
      </material>
    </visual>
    <collision>
      <origin
        xyz="0 0 -0.14"
        rpy="1.57 0 0" />
      <geometry>
        <cylinder name="rightlink3" length="0.1" radius="0.045"/>
      </geometry>
    </collision>
  </link>
  <joint
    name="rightjoint3"
    type="revolute">
    <origin
      xyz="0.078 0 -0.15861"
      rpy="0 0 0" />
    <parent
      link="rightlink2" />
    <child
      link="rightlink3" />
    <axis
      xyz="0 0 -1" />
    <limit
      lower="-1"
      upper="1"
      effort="51"
      velocity="6.28" />
  </joint>
  <link
    name="rightlink4">
    <inertial>
      <origin
        xyz="-0.00548131462526676 0.0175313657999077 -0.119815862806828"
        rpy="0 0 0" />
      <mass
        value="1.19197938223878" />
      <inertia
        ixx="0.0083510225009781"
        ixy="-6.94045904539586E-06"
        ixz="-4.75453385915807E-05"
        iyy="0.00895331142745801"
        iyz="0.000802127027367239"
        izz="0.00153401306836993" />
    </inertial>
    <visual>
      <origin
        xyz="0 0 0"
        rpy="0 0 0" />
      <geometry>
        <mesh
          filename="../meshes/rightlink4.STL" />
      </geometry>
      <material
        name="">
        <color
          rgba="0.898039215686275 0.917647058823529 0.929411764705882 1" />
      </material>
    </visual>
    <collision>
      <origin
        xyz="0 0.02 -0.15"
        rpy="0 0 0" />
      <geometry>
        <box name="rightlink4" size="0.07 0.08 0.16"/>
      </geometry>
    </collision>
  </link>
  <joint
    name="rightjoint4"
    type="revolute">
    <origin
      xyz="0 -0.027 -0.142"
      rpy="0 0 0" />
    <parent
      link="rightlink3" />
    <child
      link="rightlink4" />
    <axis
      xyz="0 -1 0" />
    <limit
      lower="-1"
      upper="1"
      effort="96"
      velocity="12" />
  </joint>
  <link
    name="rightlink5">
    <inertial>
      <origin
        xyz="2.0918E-06 3.5218E-08 2.6626E-09"
        rpy="0 0 0" />
      <mass
        value="0.019917" />
      <inertia
        ixx="1.8715E-06"
        ixy="-3.5362E-12"
        ixz="8.1116E-12"
        iyy="1.3811E-06"
        iyz="4.0896E-12"
        izz="1.5845E-06" />
    </inertial>
    <visual>
      <origin
        xyz="0 0 0"
        rpy="0 0 0" />
      <geometry>
        <mesh
          filename="../meshes/rightlink5.STL" />
      </geometry>
      <material
        name="">
        <color
          rgba="0.89804 0.91765 0.92941 1" />
      </material>
    </visual>

  </link>
  <joint
    name="rightjoint5"
    type="revolute">
    <origin
      xyz="-0.0062206 0.025 -0.289"
      rpy="0 0 0" />
    <parent
      link="rightlink4" />
    <child
      link="rightlink5" />
    <axis
      xyz="0 1 0" />
    <limit
      lower="-1"
      upper="1"
      effort="30"
      velocity="14" />
  </joint>
  <link
    name="rightlink6">
    <inertial>
      <origin
        xyz="0.022759 -0.00027434 -0.031905"
        rpy="0 0 0" />
      <mass
        value="0.43259" />
      <inertia
        ixx="0.0002364"
        ixy="-1.6201E-06"
        ixz="1.2495E-05"
        iyy="0.0014542"
        iyz="6.6787E-07"
        izz="0.0016393" />
    </inertial>
    <visual>
      <origin
        xyz="0 0 0"
        rpy="0 0 0" />
      <geometry>
        <mesh
          filename="../meshes/rightlink6.STL" />
      </geometry>
      <material
        name="">
        <color
          rgba="0.89804 0.91765 0.92941 1" />
      </material>
    </visual>
    <collision>
      <origin
        xyz="0 0 0"
        rpy="0 0 0" />
      <geometry>
        <mesh
          filename="../meshes/rightlink6.STL" />
      </geometry>
    </collision>
  </link>
  <joint
    name="rightjoint6"
    type="revolute">
    <origin
      xyz="0 0 0"
      rpy="0 0 0" />
    <parent
      link="rightlink5" />
    <child
      link="rightlink6" />
    <axis
      xyz="-1 0 0" />
    <limit
      lower="-1"
      upper="1"
      effort="30"
      velocity="14" />
  </joint>
  <link
    name="leftlink1">
    <inertial>
      <origin
        xyz="-0.021825 0.017592 6.1019E-06"
        rpy="0 0 0" />
      <mass
        value="0.50984" />
      <inertia
        ixx="0.00066856"
        ixy="0.00013058"
        ixz="4.5349E-07"
        iyy="0.0010013"
        iyz="-4.4975E-07"
        izz="0.00078046" />
    </inertial>
    <visual>
      <origin
        xyz="0 0 0"
        rpy="0 0 0" />
      <geometry>
        <mesh
          filename="../meshes/leftlink1.STL" />
      </geometry>
      <material
        name="">
        <color
          rgba="0.79216 0.81961 0.93333 1" />
      </material>
    </visual>

  </link>
  <joint
    name="leftjoint1"
    type="revolute">
    <origin
      xyz="0 0.091 -0.08"
      rpy="0 0 0" />
    <parent
      link="base_link" />
    <child
      link="leftlink1" />
    <axis
      xyz="0 1 0" />
    <limit
      lower="-1"
      upper="1"
      effort="96"
      velocity="12" />
  </joint>
  <link
    name="leftlink2">
    <inertial>
      <origin
        xyz="0.014318 8.5098E-07 -0.072113"
        rpy="0 0 0" />
      <mass
        value="0.95964" />
      <inertia
        ixx="0.0034274"
        ixy="-4.0702E-08"
        ixz="0.00050546"
        iyy="0.0034561"
        iyz="1.2957E-09"
        izz="0.001276" />
    </inertial>
    <visual>
      <origin
        xyz="0 0 0"
        rpy="0 0 0" />
      <geometry>
        <mesh
          filename="../meshes/leftlink2.STL" />
      </geometry>
      <material
        name="">
        <color
          rgba="0.89804 0.91765 0.92941 1" />
      </material>
    </visual>
    <collision>
      <origin
        xyz="0.08 0 -0.08"
        rpy="0 0 0" />
      <geometry>
        <box name="leftlink2" size="0.15 0.08 0.20"/>
      </geometry>
    </collision>
  </link>
  <joint
    name="leftjoint2"
    type="revolute">
    <origin
      xyz="-0.0816 0.052 -0.0002344"
      rpy="0 0 0" />
    <parent
      link="leftlink1" />
    <child
      link="leftlink2" />
    <axis
      xyz="-1 0 0" />
    <limit
      lower="-1"
      upper="1"
      effort="51"
      velocity="6.28" />
  </joint>
  <link
    name="leftlink3">
    <inertial>
      <origin
        xyz="-0.00024643 0.0080676 -0.048991"
        rpy="0 0 0" />
      <mass
        value="0.81627" />
      <inertia
        ixx="0.0022361"
        ixy="2.3108E-06"
        ixz="-1.4934E-06"
        iyy="0.002611"
        iyz="-2.4446E-05"
        izz="0.0012024" />
    </inertial>
    <visual>
      <origin
        xyz="0 0 0"
        rpy="0 0 0" />
      <geometry>
        <mesh
          filename="../meshes/leftlink3.STL" />
      </geometry>
      <material
        name="">
        <color
          rgba="0.89804 0.91765 0.92941 1" />
      </material>
    </visual>
    <collision>
      <origin
        xyz="0 0 -0.14"
        rpy="1.57 0 0" />
      <geometry>
        <cylinder name="leftlink3" length="0.1" radius="0.045"/>
      </geometry>
    </collision>
  </link>
  <joint
    name="leftjoint3"
    type="revolute">
    <origin
      xyz="0.078 0 -0.15861"
      rpy="0 0 0" />
    <parent
      link="leftlink2" />
    <child
      link="leftlink3" />
    <axis
      xyz="0 0 -1" />
    <limit
      lower="-1"
      upper="1"
      effort="51"
      velocity="6.28" />
  </joint>
  <link
    name="leftlink4">
    <inertial>
      <origin
        xyz="-0.0054767 -0.017536 -0.11984"
        rpy="0 0 0" />
      <mass
        value="1.192" />
      <inertia
        ixx="0.0083505"
        ixy="6.9307E-06"
        ixz="-4.7341E-05"
        iyy="0.0089527"
        iyz="-0.00080083"
        izz="0.0015342" />
    </inertial>
    <visual>
      <origin
        xyz="0 0 0"
        rpy="0 0 0" />
      <geometry>
        <mesh
          filename="../meshes/leftlink4.STL" />
      </geometry>
      <material
        name="">
        <color
          rgba="0.89804 0.91765 0.92941 1" />
      </material>
    </visual>
    <collision>
      <origin
        xyz="0 -0.02 -0.15"
        rpy="0 0 0" />
      <geometry>
        <box name="leftlink4" size="0.07 0.08 0.16"/>
      </geometry>
    </collision>
  </link>
  <joint
    name="leftjoint4"
    type="revolute">
    <origin
      xyz="0 0.027 -0.142"
      rpy="0 0 0" />
    <parent
      link="leftlink3" />
    <child
      link="leftlink4" />
    <axis
      xyz="0 1 0" />
    <limit
      lower="-1"
      upper="1"
      effort="96"
      velocity="12" />
  </joint>
  <link
    name="leftlink5">
    <inertial>
      <origin
        xyz="-1.2466E-08 -1.3708E-08 -3.3307E-16"
        rpy="0 0 0" />
      <mass
        value="0.017311" />
      <inertia
        ixx="1.816E-06"
        ixy="-5.4756E-15"
        ixz="-1.829E-13"
        iyy="1.28E-06"
        iyz="1.6181E-13"
        izz="1.529E-06" />
    </inertial>
    <visual>
      <origin
        xyz="0 0 0"
        rpy="0 0 0" />
      <geometry>
        <mesh
          filename="../meshes/leftlink5.STL" />
      </geometry>
      <material
        name="">
        <color
          rgba="0.89804 0.91765 0.92941 1" />
      </material>
    </visual>

  </link>
  <joint
    name="leftjoint5"
    type="revolute">
    <origin
      xyz="-0.0062437 -0.023 -0.289"
      rpy="0 0 0" />
    <parent
      link="leftlink4" />
    <child
      link="leftlink5" />
    <axis
      xyz="0 -1 0" />
    <limit
      lower="-1"
      upper="1"
      effort="30"
      velocity="14" />
  </joint>
  <link
    name="leftlink6">
    <inertial>
      <origin
        xyz="0.029447 0.0002491 -0.034298"
        rpy="0 0 0" />
      <mass
        value="0.62409" />
      <inertia
        ixx="0.00034485"
        ixy="2.0692E-06"
        ixz="2.4046E-05"
        iyy="0.0022494"
        iyz="-8.7171E-07"
        izz="0.0025291" />
    </inertial>
    <visual>
      <origin
        xyz="0 0 0"
        rpy="0 0 0" />
      <geometry>
        <mesh
          filename="../meshes/leftlink6.STL" />
      </geometry>
      <material
        name="">
        <color
          rgba="0.89804 0.91765 0.92941 1" />
      </material>
    </visual>
    <collision>
      <origin
        xyz="0 0 0"
        rpy="0 0 0" />
      <geometry>
        <mesh
          filename="../meshes/leftlink6.STL" />
      </geometry>
    </collision>
  </link>
  <joint
    name="leftjoint6"
    type="revolute">
    <origin
      xyz="0 0 0"
      rpy="0 0 0" />
    <parent
      link="leftlink5" />
    <child
      link="leftlink6" />
    <axis
      xyz="1 0 0" />
    <limit
      lower="-1"
      upper="1"
      effort="30"
      velocity="14" />
  </joint>
</robot>