<?xml version="1.0" encoding="utf-8"?>
<!-- This URDF was automatically created by SolidWorks to URDF Exporter! Originally created by Stephen Brawner (brawner@gmail.com)
     Commit Version: 1.6.0-4-g7f85cfe  Build Version: 1.6.7995.38578
     For more information, please see http://wiki.ros.org/sw_urdf_exporter -->
<robot
  name="alexbotmini">
  <link
    name="base_link">
    <inertial>
      <origin
        xyz="0.000311388117943606 0.0201573224730091 0.085299472946699"
        rpy="0 0 0" />
      <mass
        value="7.35718055319755" />
      <inertia
        ixx="0.0246775561676913"
        ixy="2.54918167209979E-07"
        ixz="2.15787427927021E-05"
        iyy="0.0305950136713039"
        iyz="-1.80091664078602E-07"
        izz="0.0207592714045593" />
    </inertial>
    <visual>
      <origin
        xyz="0 0 0"
        rpy="0 0 0" />
      <geometry>
        <mesh
          filename="package://alexbotmini/meshes/base_link.STL" />
      </geometry>
      <material
        name="">
        <color
          rgba="0.752941176470588 0.752941176470588 0.752941176470588 1" />
      </material>
    </visual>
    <collision>
      <origin
        xyz="0 0 0"
        rpy="0 0 0" />
      <geometry>
        <mesh
          filename="package://alexbotmini/meshes/base_link.STL" />
      </geometry>
    </collision>
  </link>
  <link
    name="rightlink1">
    <inertial>
      <origin
        xyz="0.0167755940950418 -0.0212415354979873 -0.000172073733663056"
        rpy="0 0 0" />
      <mass
        value="0.523827457014568" />
      <inertia
        ixx="0.00101779637774428"
        ixy="0.000130367646497896"
        ixz="1.03512039721392E-06"
        iyy="0.00067717587675433"
        iyz="-1.36330714602316E-06"
        izz="0.000789264166468258" />
    </inertial>
    <visual>
      <origin
        xyz="0 0 0"
        rpy="0 0 0" />
      <geometry>
        <mesh
          filename="package://alexbotmini/meshes/rightlink1.STL" />
      </geometry>
      <material
        name="">
        <color
          rgba="0.792156862745098 0.819607843137255 0.933333333333333 1" />
      </material>
    </visual>
    <collision>
      <origin
        xyz="0 0 0"
        rpy="0 0 0" />
      <geometry>
        <mesh
          filename="package://alexbotmini/meshes/rightlink1.STL" />
      </geometry>
    </collision>
  </link>
  <joint
    name="rightjoint1"
    type="revolute">
    <origin
      xyz="0.091 0.02325 -0.0998"
      rpy="0 0 0" />
    <parent
      link="base_link" />
    <child
      link="rightlink1" />
    <axis
      xyz="1 0 0" />
    <limit
      lower="-1"
      upper="1"
      effort="96"
      velocity="100" />
  </joint>
  <link
    name="rightlink2">
    <inertial>
      <origin
        xyz="0.00085874 0.014972 -0.071981"
        rpy="0 0 0" />
      <mass
        value="0.95964" />
      <inertia
        ixx="0.0034544"
        ixy="-5.9071E-06"
        ixz="2.4951E-05"
        iyy="0.0034199"
        iyz="0.00052407"
        izz="0.0012852" />
    </inertial>
    <visual>
      <origin
        xyz="0 0 0"
        rpy="0 0 0" />
      <geometry>
        <mesh
          filename="package://alexbotmini/meshes/rightlink2.STL" />
      </geometry>
      <material
        name="">
        <color
          rgba="0.89804 0.91765 0.92941 1" />
      </material>
    </visual>
    <collision>
      <origin
        xyz="0 0 0"
        rpy="0 0 0" />
      <geometry>
        <mesh
          filename="package://alexbotmini/meshes/rightlink2.STL" />
      </geometry>
    </collision>
  </link>
  <joint
    name="rightjoint2"
    type="revolute">
    <origin
      xyz="0.052 -0.081599 -0.00047085"
      rpy="0 0 0" />
    <parent
      link="rightlink1" />
    <child
      link="rightlink2" />
    <axis
      xyz="0 1 0" />
    <limit
      lower="-1"
      upper="1"
      effort="51"
      velocity="59" />
  </joint>
  <link
    name="rightlink3">
    <inertial>
      <origin
        xyz="0.00860422716293233 -0.000280475945752909 -0.048747554158768"
        rpy="0 0 0" />
      <mass
        value="0.81499254145314" />
      <inertia
        ixx="0.00260705796968271"
        ixy="-3.97343793009279E-05"
        ixz="-8.48169546695807E-06"
        iyy="0.00223619726742382"
        iyz="1.18609719859346E-05"
        izz="0.00120600722749322" />
    </inertial>
    <visual>
      <origin
        xyz="0 0 0"
        rpy="0 0 0" />
      <geometry>
        <mesh
          filename="package://alexbotmini/meshes/rightlink3.STL" />
      </geometry>
      <material
        name="">
        <color
          rgba="0.898039215686275 0.917647058823529 0.929411764705882 1" />
      </material>
    </visual>
    <collision>
      <origin
        xyz="0 0 0"
        rpy="0 0 0" />
      <geometry>
        <mesh
          filename="package://alexbotmini/meshes/rightlink3.STL" />
      </geometry>
    </collision>
  </link>
  <joint
    name="rightjoint3"
    type="revolute">
    <origin
      xyz="0.001813 0.079368 -0.15792"
      rpy="0 0 0" />
    <parent
      link="rightlink2" />
    <child
      link="rightlink3" />
    <axis
      xyz="0 0 1" />
    <limit
      lower="-1"
      upper="1"
      effort="51"
      velocity="59" />
  </joint>
  <link
    name="rightlink4">
    <inertial>
      <origin
        xyz="-0.017015 -0.0064542 -0.11979"
        rpy="0 0 0" />
      <mass
        value="1.192" />
      <inertia
        ixx="0.0089616"
        ixy="-7.0893E-05"
        ixz="-0.00074007"
        iyy="0.0083536"
        iyz="-0.00012444"
        izz="0.0015232" />
    </inertial>
    <visual>
      <origin
        xyz="0 0 0"
        rpy="0 0 0" />
      <geometry>
        <mesh
          filename="package://alexbotmini/meshes/rightlink4.STL" />
      </geometry>
      <material
        name="">
        <color
          rgba="0.89804 0.91765 0.92941 1" />
      </material>
    </visual>
    <collision>
      <origin
        xyz="0 0 0"
        rpy="0 0 0" />
      <geometry>
        <mesh
          filename="package://alexbotmini/meshes/rightlink4.STL" />
      </geometry>
    </collision>
  </link>
  <joint
    name="rightjoint4"
    type="revolute">
    <origin
      xyz="0.028485 -0.0014832 -0.1417"
      rpy="0 0 0" />
    <parent
      link="rightlink3" />
    <child
      link="rightlink4" />
    <axis
      xyz="1 0 0" />
    <limit
      lower="-1"
      upper="1"
      effort="96"
      velocity="100" />
  </joint>
  <link
    name="rightlink5">
    <inertial>
      <origin
        xyz="-1.48965478286023E-08 -1.09620757055007E-08 1.11935716251566E-09"
        rpy="0 0 0" />
      <mass
        value="0.0173110583311115" />
      <inertia
        ixx="1.28548557487684E-06"
        ixy="5.35399115801573E-08"
        ixz="-5.53872156214052E-09"
        iyy="1.80766794404536E-06"
        iyz="-2.85292842298958E-08"
        izz="1.53191416375251E-06" />
    </inertial>
    <visual>
      <origin
        xyz="0 0 0"
        rpy="0 0 0" />
      <geometry>
        <mesh
          filename="package://alexbotmini/meshes/rightlink5.STL" />
      </geometry>
      <material
        name="">
        <color
          rgba="0.898039215686275 0.917647058823529 0.929411764705882 1" />
      </material>
    </visual>
    <collision>
      <origin
        xyz="0 0 0"
        rpy="0 0 0" />
      <geometry>
        <mesh
          filename="package://alexbotmini/meshes/rightlink5.STL" />
      </geometry>
    </collision>
  </link>
  <joint
    name="rightjoint5"
    type="revolute">
    <origin
      xyz="-0.02312 -0.010345 -0.28903"
      rpy="0 0 0" />
    <parent
      link="rightlink4" />
    <child
      link="rightlink5" />
    <axis
      xyz="0 1 0" />
    <limit
      lower="-1"
      upper="1"
      effort="30"
      velocity="130" />
  </joint>
  <link
    name="rightlink6">
    <inertial>
      <origin
        xyz="0.0025618 0.019132 -0.033838"
        rpy="0 0 0" />
      <mass
        value="0.4352" />
      <inertia
        ixx="0.0014423"
        ixy="-0.00012003"
        ixz="1.2849E-05"
        iyy="0.0002655"
        iyz="0.00015318"
        izz="0.0016224" />
    </inertial>
    <visual>
      <origin
        xyz="0 0 0"
        rpy="0 0 0" />
      <geometry>
        <mesh
          filename="package://alexbotmini/meshes/rightlink6.STL" />
      </geometry>
      <material
        name="">
        <color
          rgba="0.89804 0.91765 0.92941 1" />
      </material>
    </visual>
    <collision>
      <origin
        xyz="0 0 0"
        rpy="0 0 0" />
      <geometry>
        <mesh
          filename="package://alexbotmini/meshes/rightlink6.STL" />
      </geometry>
    </collision>
  </link>
  <joint
    name="rightjoint6"
    type="revolute">
    <origin
      xyz="0 0 0"
      rpy="0 0 0" />
    <parent
      link="rightlink5" />
    <child
      link="rightlink6" />
    <axis
      xyz="-1 0 0" />
    <limit
      lower="-1"
      upper="1"
      effort="30"
      velocity="130" />
  </joint>
  <link
    name="leftlink1">
    <inertial>
      <origin
        xyz="-0.0168974992642599 -0.0212399679413113 0.000309957378181569"
        rpy="0 0 0" />
      <mass
        value="0.523827453897711" />
      <inertia
        ixx="0.00101801800516087"
        ixy="-0.000130559987564589"
        ixz="2.3185700014052E-06"
        iyy="0.000677196592977303"
        iyz="2.0546182265204E-06"
        izz="0.000789021843936907" />
    </inertial>
    <visual>
      <origin
        xyz="0 0 0"
        rpy="0 0 0" />
      <geometry>
        <mesh
          filename="package://alexbotmini/meshes/leftlink1.STL" />
      </geometry>
      <material
        name="">
        <color
          rgba="0.792156862745098 0.819607843137255 0.933333333333333 1" />
      </material>
    </visual>
    <collision>
      <origin
        xyz="0 0 0"
        rpy="0 0 0" />
      <geometry>
        <mesh
          filename="package://alexbotmini/meshes/leftlink1.STL" />
      </geometry>
    </collision>
  </link>
  <joint
    name="leftjoint1"
    type="revolute">
    <origin
      xyz="-0.091 0.02325 -0.0998"
      rpy="0 0 0" />
    <parent
      link="base_link" />
    <child
      link="leftlink1" />
    <axis
      xyz="-1 0 0" />
    <limit
      lower="-1"
      upper="1"
      effort="96"
      velocity="100" />
  </joint>
  <link
    name="leftlink2">
    <inertial>
      <origin
        xyz="-0.000419251183315983 0.0132847353003804 -0.0723095172301875"
        rpy="0 0 0" />
      <mass
        value="0.959639548121109" />
      <inertia
        ixx="0.00345604798210226"
        ixy="2.79173050721232E-06"
        ixz="-1.2691059379192E-05"
        iyy="0.00344146529024522"
        iyz="0.000474454878068968"
        izz="0.00126209321371257" />
    </inertial>
    <visual>
      <origin
        xyz="0 0 0"
        rpy="0 0 0" />
      <geometry>
        <mesh
          filename="package://alexbotmini/meshes/leftlink2.STL" />
      </geometry>
      <material
        name="">
        <color
          rgba="0.898039215686275 0.917647058823529 0.929411764705882 1" />
      </material>
    </visual>
    <collision>
      <origin
        xyz="0 0 0"
        rpy="0 0 0" />
      <geometry>
        <mesh
          filename="package://alexbotmini/meshes/leftlink2.STL" />
      </geometry>
    </collision>
  </link>
  <joint
    name="leftjoint2"
    type="revolute">
    <origin
      xyz="-0.052 -0.081595 0.00093349"
      rpy="0 0 0" />
    <parent
      link="leftlink1" />
    <child
      link="leftlink2" />
    <axis
      xyz="0 1 0" />
    <limit
      lower="-1"
      upper="1"
      effort="51"
      velocity="59" />
  </joint>
  <link
    name="leftlink3">
    <inertial>
      <origin
        xyz="-0.00834051361021043 -0.00119121604748407 -0.048931883588458"
        rpy="0 0 0" />
      <mass
        value="0.816268978197084" />
      <inertia
        ixx="0.00261106322278818"
        ixy="9.33716051385581E-06"
        ixz="1.61715416107044E-05"
        iyy="0.00223604176669555"
        iyz="-1.55446888465667E-05"
        izz="0.00120243169725821" />
    </inertial>
    <visual>
      <origin
        xyz="0 0 0"
        rpy="0 0 0" />
      <geometry>
        <mesh
          filename="package://alexbotmini/meshes/leftlink3.STL" />
      </geometry>
      <material
        name="">
        <color
          rgba="0.898039215686275 0.917647058823529 0.929411764705882 1" />
      </material>
    </visual>
    <collision>
      <origin
        xyz="0 0 0"
        rpy="0 0 0" />
      <geometry>
        <mesh
          filename="package://alexbotmini/meshes/leftlink3.STL" />
      </geometry>
    </collision>
  </link>
  <joint
    name="leftjoint3"
    type="revolute">
    <origin
      xyz="-0.00092023 0.075722 -0.1597"
      rpy="0 0 0" />
    <parent
      link="leftlink2" />
    <child
      link="leftlink3" />
    <axis
      xyz="0 0 1" />
    <limit
      lower="-1"
      upper="1"
      effort="51"
      velocity="59" />
  </joint>
  <link
    name="leftlink4">
    <inertial>
      <origin
        xyz="0.0169300414817219 -0.00441394977335115 -0.119948140149906"
        rpy="0 0 0" />
      <mass
        value="1.19197432366853" />
      <inertia
        ixx="0.00896251561054918"
        ixy="7.8738754617146E-06"
        ixz="0.000754608287983503"
        iyy="0.00835068912216675"
        iyz="7.07507604306187E-06"
        izz="0.00152409831194302" />
    </inertial>
    <visual>
      <origin
        xyz="0 0 0"
        rpy="0 0 0" />
      <geometry>
        <mesh
          filename="package://alexbotmini/meshes/leftlink4.STL" />
      </geometry>
      <material
        name="">
        <color
          rgba="0.898039215686275 0.917647058823529 0.929411764705882 1" />
      </material>
    </visual>
    <collision>
      <origin
        xyz="0 0 0"
        rpy="0 0 0" />
      <geometry>
        <mesh
          filename="package://alexbotmini/meshes/leftlink4.STL" />
      </geometry>
    </collision>
  </link>
  <joint
    name="leftjoint4"
    type="revolute">
    <origin
      xyz="-0.027811 -0.0028522 -0.14181"
      rpy="0 0 0" />
    <parent
      link="leftlink3" />
    <child
      link="leftlink4" />
    <axis
      xyz="1 0 0" />
    <limit
      lower="-1"
      upper="1"
      effort="96"
      velocity="100" />
  </joint>
  <link
    name="leftlink5">
    <inertial>
      <origin
        xyz="1.40829267969433E-08 -1.20693322280818E-08 2.17467044372199E-10"
        rpy="0 0 0" />
      <mass
        value="0.0173110583311115" />
      <inertia
        ixx="1.28053140107898E-06"
        ixy="-1.63077139934842E-08"
        ixz="1.76299970938974E-09"
        iyy="1.81538469178152E-06"
        iyz="-6.88734938072459E-09"
        izz="1.52915158981421E-06" />
    </inertial>
    <visual>
      <origin
        xyz="0 0 0"
        rpy="0 0 0" />
      <geometry>
        <mesh
          filename="package://alexbotmini/meshes/leftlink5.STL" />
      </geometry>
      <material
        name="">
        <color
          rgba="0.898039215686275 0.917647058823529 0.929411764705882 1" />
      </material>
    </visual>
    <collision>
      <origin
        xyz="0 0 0"
        rpy="0 0 0" />
      <geometry>
        <mesh
          filename="package://alexbotmini/meshes/leftlink5.STL" />
      </geometry>
    </collision>
  </link>
  <joint
    name="leftjoint5"
    type="revolute">
    <origin
      xyz="0.021337 -0.0042697 -0.28916"
      rpy="0 0 0" />
    <parent
      link="leftlink4" />
    <child
      link="leftlink5" />
    <axis
      xyz="0 1 0" />
    <limit
      lower="-1"
      upper="1"
      effort="30"
      velocity="130" />
  </joint>
  <link
    name="leftlink6">
    <inertial>
      <origin
        xyz="-0.00133596375523137 0.0285835505076604 -0.0349965112948514"
        rpy="0 0 0" />
      <mass
        value="0.624059283851391" />
      <inertia
        ixx="0.00224772654959291"
        ixy="5.61658316720616E-05"
        ixz="3.14925950391239E-07"
        iyy="0.000348940417815071"
        iyz="7.6873367196187E-05"
        izz="0.00252653885656698" />
    </inertial>
    <visual>
      <origin
        xyz="0 0 0"
        rpy="0 0 0" />
      <geometry>
        <mesh
          filename="package://alexbotmini/meshes/leftlink6.STL" />
      </geometry>
      <material
        name="">
        <color
          rgba="0.898039215686275 0.917647058823529 0.929411764705882 1" />
      </material>
    </visual>
    <collision>
      <origin
        xyz="0 0 0"
        rpy="0 0 0" />
      <geometry>
        <mesh
          filename="package://alexbotmini/meshes/leftlink6.STL" />
      </geometry>
    </collision>
  </link>
  <joint
    name="leftjoint6"
    type="revolute">
    <origin
      xyz="0 0 0"
      rpy="0 0 0" />
    <parent
      link="leftlink5" />
    <child
      link="leftlink6" />
    <axis
      xyz="1 0 0" />
    <limit
      lower="-1"
      upper="1"
      effort="30"
      velocity="130" />
  </joint>
</robot>
